INFO 2022-10-18 12:05:28,880 strategy 56928 29960 Traceback (most recent call last):
  File "C:\Users\Varnit Rastogi\AppData\Local\Programs\Python\Python39\lib\site-packages\smartapi\smartConnect.py", line 188, in _request
    data = json.loads(r.content.decode("utf8"))
  File "C:\Users\Varnit Rastogi\AppData\Local\Programs\Python\Python39\lib\json\__init__.py", line 346, in loads
    return _default_decoder.decode(s)
  File "C:\Users\Varnit Rastogi\AppData\Local\Programs\Python\Python39\lib\json\decoder.py", line 337, in decode
    obj, end = self.raw_decode(s, idx=_w(s, 0).end())
  File "C:\Users\Varnit Rastogi\AppData\Local\Programs\Python\Python39\lib\json\decoder.py", line 355, in raw_decode
    raise JSONDecodeError("Expecting value", s, err.value) from None
json.decoder.JSONDecodeError: Expecting value: line 1 column 1 (char 0)

During handling of the above exception, another exception occurred:

Traceback (most recent call last):
  File "C:\Users\Varnit Rastogi\Desktop\PROJECT47_angel_updated\datamanagement\helpful_scripts\strategy.py", line 137, in login
    data = self.obj.generateSession(
  File "C:\Users\Varnit Rastogi\AppData\Local\Programs\Python\Python39\lib\site-packages\smartapi\smartConnect.py", line 228, in generateSession
    loginResultObject=self._postRequest("api.login",params)
  File "C:\Users\Varnit Rastogi\AppData\Local\Programs\Python\Python39\lib\site-packages\smartapi\smartConnect.py", line 220, in _postRequest
    return self._request(route, "POST", params)
  File "C:\Users\Varnit Rastogi\AppData\Local\Programs\Python\Python39\lib\site-packages\smartapi\smartConnect.py", line 191, in _request
    raise ex.DataException("Couldn't parse the JSON response received from the server: {content}".format(
smartapi.smartExceptions.DataException: Couldn't parse the JSON response received from the server: b'Access denied because of exceeding access rate'

